2024-06-08 19:33:53,646 - INFO   - [MainThread:<module>(): 21] - App Starting at 0.0.0.0:6869 
2024-06-08 19:36:23,304 - INFO   - [MainThread:<module>(): 21] - App Starting at 0.0.0.0:6869 
2024-06-08 19:38:09,645 - INFO   - [MainThread:<module>(): 21] - App Starting at 0.0.0.0:6869 
2024-06-08 19:38:33,294 - INFO   - [MainThread:<module>(): 21] - App Starting at 0.0.0.0:6869 
2024-06-08 19:39:54,183 - INFO   - [MainThread:<module>(): 21] - App Starting at 0.0.0.0:6869 
2024-06-08 19:41:05,602 - INFO   - [MainThread:<module>(): 21] - App Starting at 0.0.0.0:6869 
2024-06-08 19:41:58,216 - INFO   - [MainThread:<module>(): 21] - App Starting at 0.0.0.0:6869 
2024-06-08 19:44:02,938 - DEBUG  - [MainThread:__call__(): 126] - c3d1286856aa4b94930c12f58ea580c1 
2024-06-08 19:44:02,940 - INFO   - [MainThread:fetch_task(): 83] - Error while creating task : list indices must be integers or slices, not str 
2024-06-08 19:44:40,109 - INFO   - [MainThread:<module>(): 21] - App Starting at 0.0.0.0:6869 
2024-06-08 19:44:52,064 - DEBUG  - [MainThread:__call__(): 126] - c3d1286856aa4b94930c12f58ea580c1 
2024-06-08 19:45:42,060 - INFO   - [MainThread:<module>(): 21] - App Starting at 0.0.0.0:6869 
2024-06-08 19:45:45,879 - DEBUG  - [MainThread:__call__(): 126] - c3d1286856aa4b94930c12f58ea580c1 
2024-06-08 19:45:58,427 - DEBUG  - [MainThread:__call__(): 126] - c3d1286856aa4b94930c12f58ea580c1 
2024-06-08 19:45:58,429 - DEBUG  - [MainThread:fetch_task(): 80] - No data found 
2024-06-08 19:46:02,324 - DEBUG  - [MainThread:__call__(): 126] - c3d1286856aa4b94930c12f58ea580c1 
2024-06-08 19:46:13,221 - DEBUG  - [MainThread:__call__(): 126] - c3d1286856aa4b94930c12f58ea580c1 
2024-06-08 19:46:13,224 - DEBUG  - [MainThread:fetch_task(): 80] - No data found 
2024-06-08 19:46:20,696 - DEBUG  - [MainThread:__call__(): 126] - c3d1286856aa4b94930c12f58ea580c1 
2024-06-08 19:51:34,246 - INFO   - [MainThread:<module>(): 21] - App Starting at 0.0.0.0:6869 
2024-06-08 19:51:38,415 - DEBUG  - [MainThread:__call__(): 126] - c3d1286856aa4b94930c12f58ea580c1 
2024-06-08 19:51:38,421 - INFO   - [MainThread:fetch_task(): 86] - Error while creating task : 'NoneType' object has no attribute 'lower' 
2024-06-08 19:51:49,890 - INFO   - [MainThread:<module>(): 21] - App Starting at 0.0.0.0:6869 
2024-06-08 19:51:52,268 - DEBUG  - [MainThread:__call__(): 126] - c3d1286856aa4b94930c12f58ea580c1 
2024-06-08 19:52:12,263 - DEBUG  - [MainThread:__call__(): 126] - c3d1286856aa4b94930c12f58ea580c1 
2024-06-08 19:52:12,266 - DEBUG  - [MainThread:fetch_task(): 83] - No data found 
2024-06-08 19:52:41,227 - DEBUG  - [MainThread:__call__(): 126] - c3d1286856aa4b94930c12f58ea580c1 
2024-06-08 19:52:41,230 - DEBUG  - [MainThread:fetch_task(): 83] - No data found 
2024-06-08 19:52:43,112 - DEBUG  - [MainThread:__call__(): 126] - c3d1286856aa4b94930c12f58ea580c1 
2024-06-08 19:52:43,114 - DEBUG  - [MainThread:fetch_task(): 83] - No data found 
2024-06-08 19:54:15,354 - INFO   - [MainThread:<module>(): 21] - App Starting at 0.0.0.0:6869 
2024-06-08 19:54:21,067 - DEBUG  - [MainThread:__call__(): 126] - c3d1286856aa4b94930c12f58ea580c1 
2024-06-08 19:54:21,077 - INFO   - [MainThread:fetch_task(): 84] - Error while creating task : '$match' 
2024-06-08 19:54:50,168 - INFO   - [MainThread:<module>(): 21] - App Starting at 0.0.0.0:6869 
2024-06-08 19:54:52,749 - DEBUG  - [MainThread:__call__(): 126] - c3d1286856aa4b94930c12f58ea580c1 
2024-06-08 19:54:52,757 - INFO   - [MainThread:fetch_task(): 84] - Error while creating task : exception in aggregate function as A pipeline stage specification object must contain exactly one field., full error: {'ok': 0.0, 'errmsg': 'A pipeline stage specification object must contain exactly one field.', 'code': 40323, 'codeName': 'Location40323'} 
2024-06-08 19:55:34,251 - INFO   - [MainThread:<module>(): 21] - App Starting at 0.0.0.0:6869 
2024-06-08 19:55:35,906 - DEBUG  - [MainThread:__call__(): 126] - c3d1286856aa4b94930c12f58ea580c1 
2024-06-08 19:55:35,913 - INFO   - [MainThread:fetch_task(): 84] - Error while creating task : '$match' 
2024-06-08 19:55:46,930 - INFO   - [MainThread:<module>(): 21] - App Starting at 0.0.0.0:6869 
2024-06-08 19:55:48,883 - DEBUG  - [MainThread:__call__(): 126] - c3d1286856aa4b94930c12f58ea580c1 
2024-06-08 19:55:51,512 - DEBUG  - [MainThread:__call__(): 126] - c3d1286856aa4b94930c12f58ea580c1 
2024-06-08 19:56:46,469 - INFO   - [MainThread:<module>(): 21] - App Starting at 0.0.0.0:6869 
2024-06-08 19:56:50,538 - DEBUG  - [MainThread:__call__(): 126] - c3d1286856aa4b94930c12f58ea580c1 
2024-06-08 19:56:52,522 - DEBUG  - [MainThread:__call__(): 126] - c3d1286856aa4b94930c12f58ea580c1 
2024-06-08 19:57:16,875 - DEBUG  - [MainThread:__call__(): 126] - c3d1286856aa4b94930c12f58ea580c1 
2024-06-08 20:05:18,987 - INFO   - [MainThread:<module>(): 21] - App Starting at 0.0.0.0:6869 
2024-06-08 20:06:02,836 - DEBUG  - [MainThread:__call__(): 126] - c3d1286856aa4b94930c12f58ea580c1 
2024-06-08 20:06:02,843 - INFO   - [MainThread:logout(): 120] - Failed to validate : Invalid input of type: 'dict'. Convert to a bytes, string, int or float first. 
2024-06-08 20:06:13,291 - INFO   - [MainThread:<module>(): 21] - App Starting at 0.0.0.0:6869 
2024-06-08 20:06:20,356 - DEBUG  - [MainThread:__call__(): 126] - c3d1286856aa4b94930c12f58ea580c1 
2024-06-08 20:06:46,749 - INFO   - [MainThread:<module>(): 21] - App Starting at 0.0.0.0:6869 
2024-06-08 20:06:51,762 - DEBUG  - [MainThread:__call__(): 126] - c3d1286856aa4b94930c12f58ea580c1 
2024-06-08 20:08:26,800 - INFO   - [MainThread:<module>(): 21] - App Starting at 0.0.0.0:6869 
2024-06-08 20:12:20,164 - INFO   - [MainThread:<module>(): 21] - App Starting at 0.0.0.0:6869 
2024-06-08 20:12:25,996 - DEBUG  - [MainThread:_perform_authentication(): 95] - UUID exists continuing with the same for login. 
2024-06-08 20:12:35,439 - DEBUG  - [MainThread:_perform_authentication(): 95] - UUID exists continuing with the same for login. 
2024-06-08 20:14:28,647 - INFO   - [MainThread:<module>(): 21] - App Starting at 0.0.0.0:6869 
2024-06-08 20:15:07,496 - DEBUG  - [MainThread:_perform_authentication(): 95] - UUID exists continuing with the same for login. 
2024-06-08 20:15:19,200 - DEBUG  - [MainThread:_perform_authentication(): 95] - UUID exists continuing with the same for login. 
2024-06-08 20:15:29,048 - DEBUG  - [MainThread:__call__(): 153] - 28911992236f455199110230b6c61a1a 
2024-06-08 20:16:29,865 - DEBUG  - [MainThread:__call__(): 153] - 28911992236f455199110230b6c61a1a 
2024-06-08 20:20:05,598 - ERROR  - [MainThread:__call__(): 148] - Signature Expired 
Traceback (most recent call last):
  File "C:\Users\Sourav\PycharmProjects\task_management\scripts\utils\jwt.py", line 38, in validate
    return jwt.decode(
           ^^^^^^^^^^^
  File "C:\Users\Sourav\PycharmProjects\task_management\venv\Lib\site-packages\jwt\api_jwt.py", line 210, in decode
    decoded = self.decode_complete(
              ^^^^^^^^^^^^^^^^^^^^^
  File "C:\Users\Sourav\PycharmProjects\task_management\venv\Lib\site-packages\jwt\api_jwt.py", line 162, in decode_complete
    self._validate_claims(
  File "C:\Users\Sourav\PycharmProjects\task_management\venv\Lib\site-packages\jwt\api_jwt.py", line 248, in _validate_claims
    self._validate_exp(payload, now, leeway)
  File "C:\Users\Sourav\PycharmProjects\task_management\venv\Lib\site-packages\jwt\api_jwt.py", line 306, in _validate_exp
    raise ExpiredSignatureError("Signature has expired")
jwt.exceptions.ExpiredSignatureError: Signature has expired

The above exception was the direct cause of the following exception:

Traceback (most recent call last):
  File "C:\Users\Sourav\PycharmProjects\task_management\scripts\utils\authorisation.py", line 141, in __call__
    user_id = self.token_validation(
              ^^^^^^^^^^^^^^^^^^^^^^
  File "C:\Users\Sourav\PycharmProjects\task_management\scripts\utils\authorisation.py", line 60, in token_validation
    decoded_token = self.jwt.validate(token=access_token)
                    ^^^^^^^^^^^^^^^^^^^^^^^^^^^^^^^^^^^^^
  File "C:\Users\Sourav\PycharmProjects\task_management\scripts\utils\jwt.py", line 48, in validate
    raise AuthenticationError(ErrorMessages.ERROR002) from e
scripts.exceptions.module_exception.AuthenticationError: Signature Expired
2024-06-09 11:33:38,286 - INFO   - [MainThread:<module>(): 21] - App Starting at 0.0.0.0:6869 
2024-06-09 11:37:21,185 - INFO   - [MainThread:<module>(): 21] - App Starting at 0.0.0.0:6869 
2024-06-09 11:38:19,737 - INFO   - [MainThread:<module>(): 21] - App Starting at 0.0.0.0:6869 
2024-06-09 11:38:35,106 - INFO   - [MainThread:<module>(): 21] - App Starting at 0.0.0.0:6869 
2024-06-09 11:38:50,726 - INFO   - [MainThread:<module>(): 21] - App Starting at 0.0.0.0:6869 
2024-06-09 11:39:53,499 - INFO   - [MainThread:<module>(): 21] - App Starting at 0.0.0.0:6869 
2024-06-09 11:40:34,417 - INFO   - [MainThread:<module>(): 21] - App Starting at 0.0.0.0:6869 
2024-06-09 11:43:54,730 - INFO   - [MainThread:<module>(): 21] - App Starting at 0.0.0.0:6869 
2024-06-09 11:59:17,428 - INFO   - [MainThread:<module>(): 21] - App Starting at 0.0.0.0:6869 
2024-06-09 12:00:47,702 - DEBUG  - [MainThread:__call__(): 155] - d3b95e8f11494c84870fdb03c33893ac 
2024-06-09 12:01:55,365 - DEBUG  - [MainThread:__call__(): 155] - d3b95e8f11494c84870fdb03c33893ac 
2024-06-09 12:16:23,188 - INFO   - [MainThread:<module>(): 21] - App Starting at 0.0.0.0:6869 
2024-06-09 12:16:39,199 - INFO   - [MainThread:<module>(): 21] - App Starting at 0.0.0.0:6869 
2024-06-09 12:16:47,231 - INFO   - [MainThread:<module>(): 21] - App Starting at 0.0.0.0:6869 
2024-06-09 12:16:58,400 - INFO   - [MainThread:<module>(): 21] - App Starting at 0.0.0.0:6869 
2024-06-09 12:17:24,164 - INFO   - [MainThread:<module>(): 21] - App Starting at 0.0.0.0:6869 
2024-06-09 12:18:12,623 - INFO   - [MainThread:<module>(): 21] - App Starting at 0.0.0.0:6869 
2024-06-09 12:38:38,616 - INFO   - [MainThread:<module>(): 21] - App Starting at 0.0.0.0:6869 
2024-06-09 12:39:00,765 - DEBUG  - [MainThread:_perform_authentication(): 94] - UUID exists continuing with the same for login. 
2024-06-09 12:39:31,779 - DEBUG  - [MainThread:__call__(): 153] - d3b95e8f11494c84870fdb03c33893ac 
2024-06-09 12:39:51,062 - DEBUG  - [MainThread:__call__(): 153] - d3b95e8f11494c84870fdb03c33893ac 
2024-06-09 13:30:00,407 - INFO   - [MainThread:<module>(): 21] - App Starting at 0.0.0.0:6869 
2024-06-09 13:30:44,381 - INFO   - [MainThread:<module>(): 21] - App Starting at 0.0.0.0:6869 
2024-06-09 13:38:28,603 - INFO   - [MainThread:<module>(): 21] - App Starting at 0.0.0.0:6869 
2024-06-09 13:41:00,688 - INFO   - [MainThread:<module>(): 21] - App Starting at 0.0.0.0:6869 
2024-06-09 13:56:51,568 - INFO   - [MainThread:<module>(): 21] - App Starting at 0.0.0.0:6869 
2024-06-09 13:58:17,871 - INFO   - [MainThread:<module>(): 21] - App Starting at 0.0.0.0:6869 
2024-06-09 13:59:23,041 - DEBUG  - [MainThread:_perform_authentication(): 94] - UUID exists continuing with the same for login. 
2024-06-09 13:59:53,605 - ERROR  - [MainThread:__call__(): 148] - Signature Expired 
Traceback (most recent call last):
  File "C:\Users\Sourav\PycharmProjects\task-management-system\scripts\utils\jwt.py", line 37, in validate
    return jwt.decode(
           ^^^^^^^^^^^
  File "C:\Users\Sourav\AppData\Local\Programs\Python\Python311\Lib\site-packages\jwt\api_jwt.py", line 210, in decode
    decoded = self.decode_complete(
              ^^^^^^^^^^^^^^^^^^^^^
  File "C:\Users\Sourav\AppData\Local\Programs\Python\Python311\Lib\site-packages\jwt\api_jwt.py", line 162, in decode_complete
    self._validate_claims(
  File "C:\Users\Sourav\AppData\Local\Programs\Python\Python311\Lib\site-packages\jwt\api_jwt.py", line 248, in _validate_claims
    self._validate_exp(payload, now, leeway)
  File "C:\Users\Sourav\AppData\Local\Programs\Python\Python311\Lib\site-packages\jwt\api_jwt.py", line 306, in _validate_exp
    raise ExpiredSignatureError("Signature has expired")
jwt.exceptions.ExpiredSignatureError: Signature has expired

The above exception was the direct cause of the following exception:

Traceback (most recent call last):
  File "C:\Users\Sourav\PycharmProjects\task-management-system\scripts\utils\authorisation.py", line 141, in __call__
    user_id = self.token_validation(
              ^^^^^^^^^^^^^^^^^^^^^^
  File "C:\Users\Sourav\PycharmProjects\task-management-system\scripts\utils\authorisation.py", line 60, in token_validation
    decoded_token = self.jwt.validate(token=access_token)
                    ^^^^^^^^^^^^^^^^^^^^^^^^^^^^^^^^^^^^^
  File "C:\Users\Sourav\PycharmProjects\task-management-system\scripts\utils\jwt.py", line 47, in validate
    raise AuthenticationError(ErrorMessages.ERROR002) from e
scripts.exceptions.module_exception.AuthenticationError: Signature Expired
2024-06-09 14:00:03,887 - DEBUG  - [MainThread:__call__(): 153] - de51806451294fac9c6afedace3c5ecb 
2024-06-09 14:00:19,634 - DEBUG  - [MainThread:__call__(): 153] - de51806451294fac9c6afedace3c5ecb 
2024-06-09 14:00:19,637 - DEBUG  - [MainThread:fetch_task(): 96] - No data found 
2024-06-09 14:01:15,978 - DEBUG  - [MainThread:__call__(): 153] - de51806451294fac9c6afedace3c5ecb 
2024-06-09 14:01:32,868 - DEBUG  - [MainThread:__call__(): 153] - de51806451294fac9c6afedace3c5ecb 
2024-06-09 14:01:32,871 - DEBUG  - [MainThread:fetch_task(): 96] - No data found 
2024-06-09 14:01:38,685 - DEBUG  - [MainThread:__call__(): 153] - de51806451294fac9c6afedace3c5ecb 
2024-06-09 14:01:38,688 - DEBUG  - [MainThread:fetch_task(): 96] - No data found 
2024-06-09 14:02:36,980 - DEBUG  - [MainThread:__call__(): 153] - de51806451294fac9c6afedace3c5ecb 
2024-06-09 14:02:45,632 - DEBUG  - [MainThread:__call__(): 153] - de51806451294fac9c6afedace3c5ecb 
2024-06-09 14:02:45,635 - DEBUG  - [MainThread:fetch_task(): 96] - No data found 
2024-06-09 14:02:59,883 - DEBUG  - [MainThread:__call__(): 153] - de51806451294fac9c6afedace3c5ecb 
2024-06-09 14:02:59,886 - DEBUG  - [MainThread:fetch_task(): 96] - No data found 
2024-06-09 14:04:51,852 - DEBUG  - [MainThread:__call__(): 153] - de51806451294fac9c6afedace3c5ecb 
2024-06-09 14:07:12,013 - DEBUG  - [MainThread:__call__(): 153] - de51806451294fac9c6afedace3c5ecb 
2024-06-09 14:07:12,015 - INFO   - [MainThread:fetch_task(): 99] - Error while creating task : string indices must be integers, not 'str' 
2024-06-09 14:07:20,999 - INFO   - [MainThread:<module>(): 21] - App Starting at 0.0.0.0:6869 
2024-06-09 14:08:06,226 - INFO   - [MainThread:<module>(): 21] - App Starting at 0.0.0.0:6869 
2024-06-09 14:08:09,471 - DEBUG  - [MainThread:__call__(): 153] - de51806451294fac9c6afedace3c5ecb 
2024-06-09 14:08:09,491 - INFO   - [MainThread:fetch_task(): 99] - Error while creating task : string indices must be integers, not 'str' 
2024-06-09 14:08:12,290 - DEBUG  - [MainThread:__call__(): 153] - de51806451294fac9c6afedace3c5ecb 
2024-06-09 14:08:12,293 - INFO   - [MainThread:fetch_task(): 99] - Error while creating task : string indices must be integers, not 'str' 
2024-06-09 14:08:26,544 - DEBUG  - [MainThread:__call__(): 153] - de51806451294fac9c6afedace3c5ecb 
2024-06-09 14:09:01,639 - INFO   - [MainThread:fetch_task(): 99] - Error while creating task : string indices must be integers, not 'str' 
2024-06-09 14:09:03,896 - DEBUG  - [MainThread:__call__(): 153] - de51806451294fac9c6afedace3c5ecb 
2024-06-09 14:10:32,043 - INFO   - [MainThread:<module>(): 21] - App Starting at 0.0.0.0:6869 
2024-06-09 14:10:34,838 - DEBUG  - [MainThread:__call__(): 153] - de51806451294fac9c6afedace3c5ecb 
2024-06-09 14:11:35,823 - DEBUG  - [MainThread:__call__(): 153] - de51806451294fac9c6afedace3c5ecb 
2024-06-09 14:11:40,255 - INFO   - [MainThread:<module>(): 21] - App Starting at 0.0.0.0:6869 
2024-06-09 14:11:42,763 - DEBUG  - [MainThread:__call__(): 153] - de51806451294fac9c6afedace3c5ecb 
2024-06-09 14:12:22,474 - DEBUG  - [MainThread:__call__(): 153] - de51806451294fac9c6afedace3c5ecb 
2024-06-09 14:12:26,203 - DEBUG  - [MainThread:__call__(): 153] - de51806451294fac9c6afedace3c5ecb 
2024-06-09 14:12:32,643 - DEBUG  - [MainThread:__call__(): 153] - de51806451294fac9c6afedace3c5ecb 
2024-06-09 14:16:27,723 - DEBUG  - [MainThread:__call__(): 153] - de51806451294fac9c6afedace3c5ecb 
2024-06-09 14:18:12,163 - DEBUG  - [MainThread:__call__(): 153] - de51806451294fac9c6afedace3c5ecb 
2024-06-09 14:18:12,164 - INFO   - [MainThread:update_user_info(): 44] - Failed to update user info : Username already exists!! 
2024-06-09 14:19:14,596 - INFO   - [MainThread:<module>(): 21] - App Starting at 0.0.0.0:6869 
2024-06-09 14:19:43,482 - DEBUG  - [MainThread:__call__(): 153] - de51806451294fac9c6afedace3c5ecb 
2024-06-09 14:20:34,024 - DEBUG  - [MainThread:__call__(): 153] - de51806451294fac9c6afedace3c5ecb 
2024-06-09 14:20:58,264 - DEBUG  - [MainThread:__call__(): 153] - de51806451294fac9c6afedace3c5ecb 
2024-06-09 18:33:13,022 - INFO   - [MainThread:<module>(): 21] - App Starting at 0.0.0.0:6869 
2024-06-09 18:35:16,469 - INFO   - [MainThread:_perform_authentication(): 110] - Failed to validate : 400: Invalid username or password 
2024-06-09 18:35:16,469 - INFO   - [MainThread:authenticate_user(): 66] - Failed to login Invalid username or password: 400: Invalid username or password 
2024-06-09 18:35:17,204 - INFO   - [MainThread:_perform_authentication(): 110] - Failed to validate : 400: Invalid username or password 
2024-06-09 18:35:17,204 - INFO   - [MainThread:authenticate_user(): 66] - Failed to login Invalid username or password: 400: Invalid username or password 
2024-06-09 18:35:52,232 - INFO   - [MainThread:_perform_authentication(): 110] - Failed to validate : 400: Invalid username or password 
2024-06-09 18:35:52,232 - INFO   - [MainThread:authenticate_user(): 66] - Failed to login Invalid username or password: 400: Invalid username or password 
2024-06-09 18:36:07,375 - INFO   - [MainThread:_perform_authentication(): 110] - Failed to validate : 400: Invalid username or password 
2024-06-09 18:36:07,375 - INFO   - [MainThread:authenticate_user(): 66] - Failed to login Invalid username or password: 400: Invalid username or password 
2024-06-09 18:39:48,743 - DEBUG  - [MainThread:__call__(): 153] - 80437d2870fa4a17b6203bee8cd7845c 
2024-06-09 18:39:48,745 - INFO   - [MainThread:update_user_info(): 47] - Failed to update user info : Username already exists!! 
2024-06-09 18:39:53,329 - DEBUG  - [MainThread:__call__(): 153] - 80437d2870fa4a17b6203bee8cd7845c 
2024-06-09 18:41:44,837 - DEBUG  - [MainThread:__call__(): 153] - 80437d2870fa4a17b6203bee8cd7845c 
2024-06-09 18:42:43,706 - DEBUG  - [MainThread:__call__(): 153] - 80437d2870fa4a17b6203bee8cd7845c 
2024-06-09 18:43:52,147 - DEBUG  - [MainThread:__call__(): 153] - 80437d2870fa4a17b6203bee8cd7845c 
2024-06-09 18:43:52,149 - INFO   - [MainThread:fetch_task(): 99] - Error while creating task : decoding to str: need a bytes-like object, NoneType found 
2024-06-09 18:44:50,223 - DEBUG  - [MainThread:__call__(): 153] - 80437d2870fa4a17b6203bee8cd7845c 
2024-06-09 18:44:57,859 - DEBUG  - [MainThread:__call__(): 153] - 80437d2870fa4a17b6203bee8cd7845c 
2024-06-09 18:45:33,155 - DEBUG  - [MainThread:__call__(): 153] - 80437d2870fa4a17b6203bee8cd7845c 
2024-06-09 18:45:38,288 - DEBUG  - [MainThread:__call__(): 153] - 80437d2870fa4a17b6203bee8cd7845c 
2024-06-09 18:45:38,291 - DEBUG  - [MainThread:fetch_task(): 96] - No data found 
2024-06-09 18:45:58,736 - DEBUG  - [MainThread:__call__(): 153] - 80437d2870fa4a17b6203bee8cd7845c 
2024-06-09 18:46:57,087 - DEBUG  - [MainThread:__call__(): 153] - 80437d2870fa4a17b6203bee8cd7845c 
2024-06-09 18:47:16,645 - DEBUG  - [MainThread:__call__(): 153] - 80437d2870fa4a17b6203bee8cd7845c 
2024-06-09 18:48:28,388 - DEBUG  - [MainThread:__call__(): 153] - 80437d2870fa4a17b6203bee8cd7845c 
2024-06-09 18:48:32,876 - DEBUG  - [MainThread:__call__(): 153] - 80437d2870fa4a17b6203bee8cd7845c 
2024-06-09 18:51:06,464 - INFO   - [MainThread:<module>(): 21] - App Starting at 0.0.0.0:6869 
2024-06-09 18:51:52,625 - DEBUG  - [MainThread:__call__(): 153] - 80437d2870fa4a17b6203bee8cd7845c 
2024-06-09 18:52:11,108 - DEBUG  - [MainThread:__call__(): 153] - 80437d2870fa4a17b6203bee8cd7845c 
2024-06-09 18:52:14,256 - DEBUG  - [MainThread:__call__(): 153] - 80437d2870fa4a17b6203bee8cd7845c 
2024-06-09 18:52:26,537 - DEBUG  - [MainThread:__call__(): 153] - 80437d2870fa4a17b6203bee8cd7845c 
2024-06-09 18:52:29,223 - DEBUG  - [MainThread:__call__(): 153] - 80437d2870fa4a17b6203bee8cd7845c 
2024-07-28 13:11:07,095 - INFO   - [MainThread:<module>(): 21] - App Starting at 0.0.0.0:6869 
2024-07-28 13:11:44,044 - INFO   - [MainThread:<module>(): 21] - App Starting at 0.0.0.0:6869 
2024-07-28 13:11:57,382 - INFO   - [MainThread:<module>(): 21] - App Starting at 0.0.0.0:6869 
2024-07-28 13:20:25,000 - INFO   - [MainThread:<module>(): 21] - App Starting at 0.0.0.0:6869 
2024-07-28 13:20:31,027 - DEBUG  - [MainThread:_perform_authentication(): 94] - UUID exists continuing with the same for login. 
2024-07-28 13:23:14,165 - INFO   - [MainThread:<module>(): 21] - App Starting at 0.0.0.0:6869 
2024-07-28 13:24:02,828 - INFO   - [MainThread:<module>(): 21] - App Starting at 0.0.0.0:6869 
2024-07-28 13:24:51,503 - INFO   - [MainThread:<module>(): 21] - App Starting at 0.0.0.0:6869 
2024-07-28 13:28:39,387 - INFO   - [MainThread:<module>(): 21] - App Starting at 0.0.0.0:6869 
2024-07-28 13:36:34,703 - INFO   - [MainThread:<module>(): 21] - App Starting at 0.0.0.0:6869 
2024-07-28 13:36:54,422 - INFO   - [MainThread:<module>(): 21] - App Starting at 0.0.0.0:6869 
2024-07-28 13:37:45,339 - DEBUG  - [MainThread:__call__(): 153] - d849538929c140099e89da8d5c8055ba 
2024-07-28 13:38:42,164 - INFO   - [MainThread:<module>(): 21] - App Starting at 0.0.0.0:6869 
2024-07-28 13:38:45,128 - DEBUG  - [MainThread:__call__(): 153] - d849538929c140099e89da8d5c8055ba 
2024-07-28 13:39:50,602 - INFO   - [MainThread:<module>(): 21] - App Starting at 0.0.0.0:6869 
2024-07-28 13:39:56,736 - DEBUG  - [MainThread:__call__(): 153] - d849538929c140099e89da8d5c8055ba 
2024-07-28 13:42:34,909 - INFO   - [MainThread:<module>(): 21] - App Starting at 0.0.0.0:6869 
2024-07-28 13:42:46,698 - INFO   - [MainThread:<module>(): 21] - App Starting at 0.0.0.0:6869 
2024-07-28 13:42:50,842 - DEBUG  - [MainThread:__call__(): 153] - d849538929c140099e89da8d5c8055ba 
2024-07-28 13:42:56,494 - DEBUG  - [MainThread:__call__(): 153] - d849538929c140099e89da8d5c8055ba 
2024-07-28 13:42:56,501 - ERROR  - [MainThread:fetch_as_json(): 285] - Error occurred while fetching data: (psycopg.errors.UndefinedColumn) column categories.category_name does not exist
LINE 1: SELECT categories.category_id, categories.category_name, cat...
                                       ^
[SQL: SELECT categories.category_id, categories.category_name, categories.description, categories.meta 
FROM categories 
WHERE categories.category_name = %(category_name_1)s::VARCHAR]
[parameters: {'category_name_1': 'Electronics'}]
(Background on this error at: https://sqlalche.me/e/20/f405) 
2024-07-28 13:42:56,504 - ERROR  - [MainThread:insert(): 77] - Error occurred while inserting: (psycopg.errors.InFailedSqlTransaction) current transaction is aborted, commands ignored until end of transaction block
[SQL: INSERT INTO categories (category_id, category_name, description, meta) VALUES (%(category_id)s::VARCHAR, %(category_name)s::VARCHAR, %(description)s::VARCHAR, %(meta)s::JSON)]
[parameters: {'category_id': '7XzuUNhfXFNPvoNknc7Vtr', 'category_name': 'Electronics', 'description': 'sfsfsfsfsf', 'meta': Json({'created_by': 'user_dLDTBxmSwTnmc7 ... (106 chars))}]
(Background on this error at: https://sqlalche.me/e/20/2j85) 
Traceback (most recent call last):
  File "C:\Users\Sourav\AppData\Local\Programs\Python\Python311\Lib\site-packages\sqlalchemy\engine\base.py", line 1967, in _exec_single_context
    self.dialect.do_execute(
  File "C:\Users\Sourav\AppData\Local\Programs\Python\Python311\Lib\site-packages\sqlalchemy\engine\default.py", line 924, in do_execute
    cursor.execute(statement, parameters)
  File "C:\Users\Sourav\AppData\Local\Programs\Python\Python311\Lib\site-packages\psycopg\cursor.py", line 97, in execute
    raise ex.with_traceback(None)
psycopg.errors.InFailedSqlTransaction: current transaction is aborted, commands ignored until end of transaction block

The above exception was the direct cause of the following exception:

Traceback (most recent call last):
  File "C:\Users\Sourav\PycharmProjects\task-management-system\scripts\utils\sqlalchemy2_utils.py", line 74, in insert
    self.session.execute(insert_stmt)
  File "C:\Users\Sourav\AppData\Local\Programs\Python\Python311\Lib\site-packages\sqlalchemy\orm\session.py", line 2351, in execute
    return self._execute_internal(
           ^^^^^^^^^^^^^^^^^^^^^^^
  File "C:\Users\Sourav\AppData\Local\Programs\Python\Python311\Lib\site-packages\sqlalchemy\orm\session.py", line 2236, in _execute_internal
    result: Result[Any] = compile_state_cls.orm_execute_statement(
                          ^^^^^^^^^^^^^^^^^^^^^^^^^^^^^^^^^^^^^^^^
  File "C:\Users\Sourav\AppData\Local\Programs\Python\Python311\Lib\site-packages\sqlalchemy\orm\bulk_persistence.py", line 1283, in orm_execute_statement
    result = conn.execute(
             ^^^^^^^^^^^^^
  File "C:\Users\Sourav\AppData\Local\Programs\Python\Python311\Lib\site-packages\sqlalchemy\engine\base.py", line 1418, in execute
    return meth(
           ^^^^^
  File "C:\Users\Sourav\AppData\Local\Programs\Python\Python311\Lib\site-packages\sqlalchemy\sql\elements.py", line 515, in _execute_on_connection
    return connection._execute_clauseelement(
           ^^^^^^^^^^^^^^^^^^^^^^^^^^^^^^^^^^
  File "C:\Users\Sourav\AppData\Local\Programs\Python\Python311\Lib\site-packages\sqlalchemy\engine\base.py", line 1640, in _execute_clauseelement
    ret = self._execute_context(
          ^^^^^^^^^^^^^^^^^^^^^^
  File "C:\Users\Sourav\AppData\Local\Programs\Python\Python311\Lib\site-packages\sqlalchemy\engine\base.py", line 1846, in _execute_context
    return self._exec_single_context(
           ^^^^^^^^^^^^^^^^^^^^^^^^^^
  File "C:\Users\Sourav\AppData\Local\Programs\Python\Python311\Lib\site-packages\sqlalchemy\engine\base.py", line 1986, in _exec_single_context
    self._handle_dbapi_exception(
  File "C:\Users\Sourav\AppData\Local\Programs\Python\Python311\Lib\site-packages\sqlalchemy\engine\base.py", line 2353, in _handle_dbapi_exception
    raise sqlalchemy_exception.with_traceback(exc_info[2]) from e
  File "C:\Users\Sourav\AppData\Local\Programs\Python\Python311\Lib\site-packages\sqlalchemy\engine\base.py", line 1967, in _exec_single_context
    self.dialect.do_execute(
  File "C:\Users\Sourav\AppData\Local\Programs\Python\Python311\Lib\site-packages\sqlalchemy\engine\default.py", line 924, in do_execute
    cursor.execute(statement, parameters)
  File "C:\Users\Sourav\AppData\Local\Programs\Python\Python311\Lib\site-packages\psycopg\cursor.py", line 97, in execute
    raise ex.with_traceback(None)
sqlalchemy.exc.InternalError: (psycopg.errors.InFailedSqlTransaction) current transaction is aborted, commands ignored until end of transaction block
[SQL: INSERT INTO categories (category_id, category_name, description, meta) VALUES (%(category_id)s::VARCHAR, %(category_name)s::VARCHAR, %(description)s::VARCHAR, %(meta)s::JSON)]
[parameters: {'category_id': '7XzuUNhfXFNPvoNknc7Vtr', 'category_name': 'Electronics', 'description': 'sfsfsfsfsf', 'meta': Json({'created_by': 'user_dLDTBxmSwTnmc7 ... (106 chars))}]
(Background on this error at: https://sqlalche.me/e/20/2j85)
2024-07-28 13:42:56,524 - INFO   - [MainThread:create_categories(): 44] - Error while creating category : (psycopg.errors.InFailedSqlTransaction) current transaction is aborted, commands ignored until end of transaction block
[SQL: INSERT INTO categories (category_id, category_name, description, meta) VALUES (%(category_id)s::VARCHAR, %(category_name)s::VARCHAR, %(description)s::VARCHAR, %(meta)s::JSON)]
[parameters: {'category_id': '7XzuUNhfXFNPvoNknc7Vtr', 'category_name': 'Electronics', 'description': 'sfsfsfsfsf', 'meta': Json({'created_by': 'user_dLDTBxmSwTnmc7 ... (106 chars))}]
(Background on this error at: https://sqlalche.me/e/20/2j85) 
2024-07-28 13:43:22,107 - INFO   - [MainThread:<module>(): 21] - App Starting at 0.0.0.0:6869 
2024-07-28 13:43:26,876 - DEBUG  - [MainThread:__call__(): 153] - d849538929c140099e89da8d5c8055ba 
2024-07-28 13:43:51,401 - ERROR  - [MainThread:fetch_as_json(): 285] - Error occurred while fetching data: (psycopg.errors.UndefinedColumn) column categories.category_name does not exist
LINE 1: SELECT categories.category_id, categories.category_name, cat...
                                       ^
[SQL: SELECT categories.category_id, categories.category_name, categories.description, categories.meta 
FROM categories 
WHERE categories.category_name = %(category_name_1)s::VARCHAR]
[parameters: {'category_name_1': 'Electronics'}]
(Background on this error at: https://sqlalche.me/e/20/f405) 
2024-07-28 13:44:10,757 - INFO   - [MainThread:<module>(): 21] - App Starting at 0.0.0.0:6869 
2024-07-28 13:44:14,015 - DEBUG  - [MainThread:__call__(): 153] - d849538929c140099e89da8d5c8055ba 
2024-07-28 13:44:15,570 - DEBUG  - [MainThread:__call__(): 153] - d849538929c140099e89da8d5c8055ba 
2024-07-28 13:44:15,575 - INFO   - [MainThread:create_categories(): 44] - Error while creating category : Category already exists!! 
2024-07-28 13:44:31,840 - DEBUG  - [MainThread:__call__(): 153] - d849538929c140099e89da8d5c8055ba 
2024-07-28 13:44:31,845 - INFO   - [MainThread:update_categories(): 75] - Error while creating category : Invalid category_id !! 
2024-07-28 13:44:50,477 - DEBUG  - [MainThread:__call__(): 153] - d849538929c140099e89da8d5c8055ba 
2024-07-28 13:44:50,481 - INFO   - [MainThread:update_categories(): 75] - Error while creating category : list indices must be integers or slices, not str 
2024-07-28 13:45:07,703 - INFO   - [MainThread:<module>(): 21] - App Starting at 0.0.0.0:6869 
2024-07-28 13:45:16,830 - DEBUG  - [MainThread:__call__(): 153] - d849538929c140099e89da8d5c8055ba 
2024-07-28 13:45:25,804 - INFO   - [MainThread:update_categories(): 75] - Error while creating category : list indices must be integers or slices, not str 
2024-07-28 13:45:46,997 - DEBUG  - [MainThread:__call__(): 153] - d849538929c140099e89da8d5c8055ba 
2024-07-28 13:47:16,575 - INFO   - [MainThread:<module>(): 21] - App Starting at 0.0.0.0:6869 
2024-07-28 13:47:19,979 - DEBUG  - [MainThread:__call__(): 153] - d849538929c140099e89da8d5c8055ba 
2024-07-28 13:47:31,386 - DEBUG  - [MainThread:__call__(): 153] - d849538929c140099e89da8d5c8055ba 
2024-07-28 13:47:31,391 - INFO   - [MainThread:update_categories(): 75] - Error while creating category : Invalid category_id !! 
2024-07-28 13:47:40,437 - DEBUG  - [MainThread:__call__(): 153] - d849538929c140099e89da8d5c8055ba 
2024-07-28 13:47:49,030 - DEBUG  - [MainThread:__call__(): 153] - d849538929c140099e89da8d5c8055ba 
2024-07-28 13:47:53,722 - DEBUG  - [MainThread:__call__(): 153] - d849538929c140099e89da8d5c8055ba 
2024-07-28 13:54:56,408 - INFO   - [MainThread:<module>(): 21] - App Starting at 0.0.0.0:6869 
2024-07-28 13:56:29,786 - ERROR  - [MainThread:__call__(): 148] - Signature Expired 
Traceback (most recent call last):
  File "C:\Users\Sourav\PycharmProjects\task-management-system\scripts\utils\jwt.py", line 37, in validate
    return jwt.decode(
           ^^^^^^^^^^^
  File "C:\Users\Sourav\AppData\Local\Programs\Python\Python311\Lib\site-packages\jwt\api_jwt.py", line 210, in decode
    decoded = self.decode_complete(
              ^^^^^^^^^^^^^^^^^^^^^
  File "C:\Users\Sourav\AppData\Local\Programs\Python\Python311\Lib\site-packages\jwt\api_jwt.py", line 162, in decode_complete
    self._validate_claims(
  File "C:\Users\Sourav\AppData\Local\Programs\Python\Python311\Lib\site-packages\jwt\api_jwt.py", line 248, in _validate_claims
    self._validate_exp(payload, now, leeway)
  File "C:\Users\Sourav\AppData\Local\Programs\Python\Python311\Lib\site-packages\jwt\api_jwt.py", line 306, in _validate_exp
    raise ExpiredSignatureError("Signature has expired")
jwt.exceptions.ExpiredSignatureError: Signature has expired

The above exception was the direct cause of the following exception:

Traceback (most recent call last):
  File "C:\Users\Sourav\PycharmProjects\task-management-system\scripts\utils\authorisation.py", line 141, in __call__
    user_id = self.token_validation(
              ^^^^^^^^^^^^^^^^^^^^^^
  File "C:\Users\Sourav\PycharmProjects\task-management-system\scripts\utils\authorisation.py", line 60, in token_validation
    decoded_token = self.jwt.validate(token=access_token)
                    ^^^^^^^^^^^^^^^^^^^^^^^^^^^^^^^^^^^^^
  File "C:\Users\Sourav\PycharmProjects\task-management-system\scripts\utils\jwt.py", line 47, in validate
    raise AuthenticationError(ErrorMessages.ERROR002) from e
scripts.exceptions.module_exception.AuthenticationError: Signature Expired
2024-07-28 13:57:08,095 - DEBUG  - [MainThread:_perform_authentication(): 94] - UUID exists continuing with the same for login. 
2024-07-28 13:57:29,853 - DEBUG  - [MainThread:__call__(): 153] - d849538929c140099e89da8d5c8055ba 
2024-07-28 13:57:29,854 - ERROR  - [MainThread:fetch_as_json(): 286] - Error occurred while fetching data: 'Query' object has no attribute 'compile' 
2024-07-28 13:57:29,854 - DEBUG  - [MainThread:fetch_categories(): 84] - No data found 
2024-07-28 14:30:04,535 - DEBUG  - [MainThread:_perform_authentication(): 94] - UUID exists continuing with the same for login. 
2024-07-28 14:30:16,936 - DEBUG  - [MainThread:__call__(): 153] - d849538929c140099e89da8d5c8055ba 
2024-07-28 14:30:16,937 - ERROR  - [MainThread:fetch_as_json(): 286] - Error occurred while fetching data: 'Query' object has no attribute 'compile' 
2024-07-28 14:30:16,937 - DEBUG  - [MainThread:fetch_categories(): 84] - No data found 
2024-07-28 14:31:26,582 - INFO   - [MainThread:<module>(): 21] - App Starting at 0.0.0.0:6869 
2024-07-28 14:31:31,149 - DEBUG  - [MainThread:__call__(): 153] - d849538929c140099e89da8d5c8055ba 
2024-07-28 14:33:11,650 - INFO   - [MainThread:<module>(): 21] - App Starting at 0.0.0.0:6869 
2024-07-28 14:33:17,119 - DEBUG  - [MainThread:__call__(): 153] - d849538929c140099e89da8d5c8055ba 
2024-07-28 14:34:10,661 - INFO   - [MainThread:<module>(): 21] - App Starting at 0.0.0.0:6869 
2024-07-28 14:34:24,613 - DEBUG  - [MainThread:__call__(): 153] - d849538929c140099e89da8d5c8055ba 
2024-07-28 14:34:27,380 - DEBUG  - [MainThread:__call__(): 153] - d849538929c140099e89da8d5c8055ba 
2024-07-28 14:34:53,039 - DEBUG  - [MainThread:__call__(): 153] - d849538929c140099e89da8d5c8055ba 
2024-07-28 14:34:56,232 - DEBUG  - [MainThread:__call__(): 153] - d849538929c140099e89da8d5c8055ba 
2024-07-28 14:34:56,237 - DEBUG  - [MainThread:fetch_categories(): 85] - No data found 
2024-07-28 14:35:04,938 - DEBUG  - [MainThread:__call__(): 153] - d849538929c140099e89da8d5c8055ba 
2024-07-28 14:35:04,943 - DEBUG  - [MainThread:fetch_categories(): 85] - No data found 
2024-07-28 14:35:15,253 - DEBUG  - [MainThread:__call__(): 153] - d849538929c140099e89da8d5c8055ba 
2024-07-28 14:35:32,577 - DEBUG  - [MainThread:__call__(): 153] - d849538929c140099e89da8d5c8055ba 
2024-07-28 14:35:32,582 - DEBUG  - [MainThread:fetch_categories(): 85] - No data found 
2024-07-28 14:35:54,011 - DEBUG  - [MainThread:__call__(): 153] - d849538929c140099e89da8d5c8055ba 
2024-07-28 14:35:54,018 - DEBUG  - [MainThread:fetch_categories(): 85] - No data found 
2024-07-28 14:35:58,669 - DEBUG  - [MainThread:__call__(): 153] - d849538929c140099e89da8d5c8055ba 
2024-07-28 14:35:58,673 - DEBUG  - [MainThread:fetch_categories(): 85] - No data found 
2024-07-28 14:36:03,374 - INFO   - [MainThread:<module>(): 21] - App Starting at 0.0.0.0:6869 
2024-07-28 14:36:09,145 - DEBUG  - [MainThread:__call__(): 153] - d849538929c140099e89da8d5c8055ba 
2024-07-28 14:38:59,333 - INFO   - [MainThread:<module>(): 21] - App Starting at 0.0.0.0:6869 
2024-07-28 14:39:02,395 - DEBUG  - [MainThread:__call__(): 153] - d849538929c140099e89da8d5c8055ba 
2024-07-28 17:42:02,031 - INFO   - [MainThread:<module>(): 21] - App Starting at 0.0.0.0:6869 
2024-07-28 17:43:04,467 - INFO   - [MainThread:<module>(): 21] - App Starting at 0.0.0.0:6869 
2024-07-28 17:43:29,722 - DEBUG  - [MainThread:__call__(): 153] - 184354c6eb1d42d1b0c489f3144ef4cb 
2024-07-28 17:43:29,729 - DEBUG  - [MainThread:fetch_transaction(): 49] - No data found 
2024-07-28 17:43:39,083 - DEBUG  - [MainThread:__call__(): 153] - 184354c6eb1d42d1b0c489f3144ef4cb 
2024-07-28 17:43:39,087 - DEBUG  - [MainThread:fetch_transaction(): 49] - No data found 
2024-07-28 17:43:51,588 - DEBUG  - [MainThread:__call__(): 153] - 184354c6eb1d42d1b0c489f3144ef4cb 
2024-07-28 17:43:51,588 - INFO   - [MainThread:fetch_transaction(): 52] - Error while fetch transaction : 'colId' 
2024-07-28 17:43:57,225 - DEBUG  - [MainThread:__call__(): 153] - 184354c6eb1d42d1b0c489f3144ef4cb 
2024-07-28 17:43:57,229 - DEBUG  - [MainThread:fetch_transaction(): 49] - No data found 
2024-07-28 17:44:04,452 - INFO   - [MainThread:<module>(): 21] - App Starting at 0.0.0.0:6869 
2024-07-28 17:44:09,291 - DEBUG  - [MainThread:__call__(): 153] - 184354c6eb1d42d1b0c489f3144ef4cb 
2024-07-28 17:44:38,325 - INFO   - [MainThread:<module>(): 21] - App Starting at 0.0.0.0:6869 
2024-07-28 17:45:44,757 - DEBUG  - [MainThread:__call__(): 153] - 184354c6eb1d42d1b0c489f3144ef4cb 
2024-07-28 17:45:58,574 - INFO   - [MainThread:<module>(): 21] - App Starting at 0.0.0.0:6869 
2024-07-28 17:46:01,708 - DEBUG  - [MainThread:__call__(): 153] - 184354c6eb1d42d1b0c489f3144ef4cb 
2024-07-28 17:46:12,067 - DEBUG  - [MainThread:__call__(): 153] - 184354c6eb1d42d1b0c489f3144ef4cb 
2024-07-28 17:46:46,499 - DEBUG  - [MainThread:__call__(): 153] - 184354c6eb1d42d1b0c489f3144ef4cb 
2024-07-28 17:46:49,612 - DEBUG  - [MainThread:__call__(): 153] - 184354c6eb1d42d1b0c489f3144ef4cb 
2024-07-28 17:46:49,617 - DEBUG  - [MainThread:fetch_transaction(): 49] - No data found 
2024-07-28 17:47:06,938 - DEBUG  - [MainThread:__call__(): 153] - 184354c6eb1d42d1b0c489f3144ef4cb 
2024-07-28 17:47:10,407 - DEBUG  - [MainThread:__call__(): 153] - 184354c6eb1d42d1b0c489f3144ef4cb 
2024-07-28 17:47:10,412 - DEBUG  - [MainThread:fetch_transaction(): 49] - No data found 
2024-07-28 17:47:13,235 - DEBUG  - [MainThread:__call__(): 153] - 184354c6eb1d42d1b0c489f3144ef4cb 
2024-07-28 17:47:26,252 - DEBUG  - [MainThread:__call__(): 153] - 184354c6eb1d42d1b0c489f3144ef4cb 
2024-07-28 17:47:28,656 - DEBUG  - [MainThread:__call__(): 153] - 184354c6eb1d42d1b0c489f3144ef4cb 
2024-07-28 17:47:32,289 - DEBUG  - [MainThread:__call__(): 153] - 184354c6eb1d42d1b0c489f3144ef4cb 
2024-07-28 17:47:47,650 - INFO   - [MainThread:<module>(): 21] - App Starting at 0.0.0.0:6869 
2024-07-28 17:48:01,191 - DEBUG  - [MainThread:__call__(): 153] - 184354c6eb1d42d1b0c489f3144ef4cb 
2024-07-28 17:48:26,310 - INFO   - [MainThread:<module>(): 21] - App Starting at 0.0.0.0:6869 
2024-07-28 17:48:29,771 - DEBUG  - [MainThread:__call__(): 153] - 184354c6eb1d42d1b0c489f3144ef4cb 
2024-07-28 17:48:38,093 - DEBUG  - [MainThread:__call__(): 153] - 184354c6eb1d42d1b0c489f3144ef4cb 
2024-07-28 19:03:15,685 - INFO   - [MainThread:<module>(): 21] - App Starting at 0.0.0.0:6869 
2024-07-28 19:03:31,433 - DEBUG  - [MainThread:_perform_authentication(): 94] - UUID exists continuing with the same for login. 
